Workbook

Sheet Sheet1
A1: Brought to you by KnowyourGST.com Visit KnowyourGST.com for Indian Tax Law GST Billing Software Professionals Listing Job Search

Sheet Cover Page
A6: DETAILED PROJECT REPORT
D8: OF
A10: Ayan Sharma
E27: Prepared by:
E28: Shriya Shetty

Sheet Sign
E2: ACH & ASSOCIATES
F3: Chartered Accountants
D8: To Whomsoever It May Concernd
B12: This is to certify that the attached financial projections for AYAN SHARMA
B14: has been prepared by us in accordance with the accepted trend,
B16: normal practice and in accordance with the rules set by relevant statutory authorities.
B19: Since these are projections and not actual figures we do not express any opinion on
B21: these projections. The limitation of projections shall be applied by the reader of
B23: these report / projections. This certificate had been issued to certify that we had only
B25: prepared / compiled the projections exercising due care to consider the present trend
B27: and normal practice and in accordance with the rules set by the statutory authorities.
B29: The project report had been prepared to be submitted before financial institutions for
B31: establishing financial viability of the project and should be utilized with due caution.
B42: Place : Mumbai
B43: Date : 25-04-2025

Sheet Index
A2: ='Cover Page'!A10:G10 -> Ayan Sharma
B4: I N D E X
A5: SL. | B5: C O N T E N T S | C5: PAGES
B7: CHAPTER :
A8: 1 | B8: PROJECT AT GLANCE | C8: 4
A9: 2 | B9: COST OF THE PROJECT AND MEANS OF FINANCE | C9: 5
A10: 3 | B10: PROJECTIONS AND PROFITABILITY STATEMENT | C10: 6
A11: 4 | B11: CASH - FLOW STATEMENT | C11: 7
A12: 5 | B12: BALANCE SHEET | C12: 8
B14: A N N E X U R E S
A15: 1 | B15: DEPRECIATION SCHEDULE | C15: 9
A16: 2 | B16: BREAK EVEN ANALYSIS | C16: 10
A17: 3 | B17: FINANCIAL INDICATERS | C17: 11
A18: 4 | B18: INTEREST SCHEDULE | C18: 12
A19: 5 | B19: DEBT COVERAGE RATIO | C19: 14
A20: 6 | B20: ANALYSIS ON RETURN ON INVESTMENT | C20: 15
A21: 7 | B21: ASSUMPTIONS | C21: 16

Sheet Project
B1: =Index!A2 -> Ayan Sharma
B3: STATEMENT NO. 1
A5: PROJECT AT GLANCE
A7: 1 | B7: TRADE NAME | C7: : | D7: =B1 -> Ayan Sharma
A9: 2 | B9: PROPRIETOR'S NAME | C9: : | D9: =D7 -> Ayan Sharma
A11: 3 | B11: FATHER'S NAME | C11: : | D11: MR.MURAR JI YADAV
A13: 4 | B13: PAN | C13: : | D13: ASIPY5985C
A15: 5 | B15: AADHAR | C15: : | D15: 3316-9177-8268
A17: 6 | B17: MOBILE | C17: : | D17: 8574134650
A19: 7 | B19: UNIT ADDRESS | C19: : | D19: RAJATALAB, BHIBHARIPUR VARANASI UP- 221311
A21: 8 | B21: CONSTITUTION | C21: : | D21: PROPRIETORSHIP
A23: 9 | B23: TYPE OF THE PROJECT | C23: : | D23: PURCHASE OF COMMERCIAL PLANT / VEHICLES
A25: 10 | B25: ACTIVITY OF THE PROJECT | C25: : | D25: EXTRACTION OF SOIL & CRUX MATERIALS
A27: 11 | B27: SCHEME OF THE PROJECT | C27: : | D27: COMMERCIAL LOAN
A29: 12 | B29: TOTAL COST OF THE PROJECT | C29: : | D29: =Cost!C29 -> 10209070
A31: 13 | B31: AMOUNT OF BANK LOAN | C31: : | D31: =Cost!C35+Cost!C36 -> 2300000
A33: 14 | B33: PROMOTER'S CONTRIBUTION | C33: : | D33: =Cost!C33+Cost!C34 -> 7609070
A35: 15 | B35: GOVERNMENT SUBSIDY | C35: : | D35: 0
A37: 16 | B37: INTEREST | C37: : | D37: 0.0975
A39: 17 | B39: DEBT EQUITY RATIO | C39: : | D39: =Cost!E35/Cost!E34 -> 3.3082913 | E39: :1
A41: 18 | B41: DEBT COVERAGE RATIO | C41: : | D41: ='Annex 5 DSCR'!B24 -> #DIV/0!
A43: 19 | B43: GROSS PROFIT RATIO | C43: : | D43: =profit!B24/profit!B11*100 -> 6.6407679 | E43: First Year Operation.
A45: 20 | B45: NET PROFIT RATIO | C45: : | D45: =profit!B32/profit!B11*100 -> 6.6407679 | E45: First Year Operation.
A47: 21 | B47: RETURN ON INVESTMENT | C47: : | D47: ='Annex 6 ROI'!B34 -> 22.324322 | E47: %

Sheet Cost
A1: ='Cover Page'!A10:G10 -> Ayan Sharma
A4: STATEMENT NO. 2
A6: COST OF THE PROJECT AND MEANS OF FINANCE:
A9: The project cost has been estimated at Rs. | C9: =C29 -> 10209070
A11: Brief details of the project cost is given below
A13: Cost of the project | B13: :
A14: Particulars | C14: Total
A16: Construction | C16: 0
A18: Machinery & Equipments | C18: =SUM(B19:B23) -> 9909070
A19: Machine | B19: 3400000
A20: Previous contribution | B20: 6509070
A26: Working Capital | C26: 300000
A29: Total | C29: =SUM(C15:C28) -> 10209070
A31: Means of Finance | B31: :
A32: Particulars | B32: Margin | C32: Total
A33: Proprietor's Contribution | B33: 0.2973 | C33: 7309070
A34: Proprietor's Contribution- Working Capital | B34: 0.08 | C34: 300000 | E34: =C36+C35 -> 2300000
A35: Loan from Bank | B35: 0.6217 | C35: 2300000 | E35: =C34+C33 -> 7609070
A36: Working Capital from Bank | C36: 0
A38: Total | C38: =SUM(C33:C37) -> 9909070

Sheet profit
A1: =Cost!A1 -> Ayan Sharma
A4: STATEMENT NO.3
A5: PROJECTIONS AND PROFITABILITY STATEMENT
A6: PARTICULARS | B6: Operating years
B7: 2026 | C7: 2027 | D7: 2028 | E7: 2029 | F7: 2030
A8: A.INCOME:
A9: Income from Sale Activities | B9: 15811417 | C9: =B9+(B9*3%) -> 16285760 | D9: =C9+(C9*4%) -> 16937190 | E9: =D9+(D9*4%) -> 17614677 | F9: =E9+(E9*5%) -> 18495411
B11: =SUM(B9:B10) -> 15811417 | C11: =SUM(C9:C10) -> 16285760 | D11: =SUM(D9:D10) -> 16937190 | E11: =SUM(E9:E10) -> 17614677 | F11: =SUM(F9:F10) -> 18495411
A12: B. EXPENSES:
A13: Driver Salary | B13: =30000*7*12 -> 2520000 | C13: =B13*10%+B13 -> 2772000 | D13: =C13*10%+C13 -> 3049200 | E13: =D13*10%+D13 -> 3354120 | F13: =E13*10%+E13 -> 3689532
A14: Interest on Vehicals Loan | B14: =308000*12 -> 3696000 | C14: =276000*12 -> 3312000 | D14: =247000*12 -> 2964000 | E14: =198000*12 -> 2376000 | F14: =164000*12 -> 1968000
A15: Power & Fuel | B15: =20000*25*12 -> 6000000 | C15: =B15+(B15*10%) -> 6600000 | D15: =C15+(C15*10%) -> 7260000 | E15: =D15+(D15*10%) -> 7986000 | F15: =E15+(E15*10%) -> 8784600
A16: Repair & maintenance | B16: 300000 | C16: =B16+(B16*20%) -> 360000 | D16: =C16+(C16*20%) -> 432000 | E16: =D16+(D16*20%) -> 518400 | F16: =E16+(E16*20%) -> 622080
A17: Toll tax | B17: 30000 | C17: 30000 | D17: 30000 | E17: 30000 | F17: 30000
A18: Mobile & Internet charges | B18: 11500 | C18: =B18+(B18*5%) -> 12075 | D18: =C18+(C18*5%) -> 12678.75 | E18: =D18+(D18*5%) -> 13312.688 | F18: =E18+(E18*5%) -> 13978.322
A19: Operator charges | B19: 650000 | C19: =B19*10%+B19 -> 715000 | D19: =C19*10%+C19 -> 786500 | E19: =D19*10%+D19 -> 865150 | F19: =E19*10%+E19 -> 951665
A20: Insurance & Taxes | B20: 300000 | C20: =B20-10000 -> 290000 | D20: =C20-15000 -> 275000 | E20: =D20-25000 -> 250000 | F20: =E20-27000 -> 223000
A21: Depreciation | B21: =Depr.!B22 -> 1253917.5 | C21: =Depr.!C22 -> 1065829.9 | D21: =Depr.!D22 -> 905955.39 | E21: =Depr.!E22 -> 770062.08 | F21: =Depr.!F22 -> 654552.77
A22: Cost of Operations | B22: =SUM(B13:B21) -> 14761418 | C22: =SUM(C13:C21) -> 15156905 | D22: =SUM(D13:D21) -> 15715334 | E22: =SUM(E13:E21) -> 16163045 | F22: =SUM(F13:F21) -> 16937408
A24: C. Gross Profit [ A - B ] | B24: =B11-B22 -> 1049999.5 | C24: =C11-C22 -> 1128854.6 | D24: =D11-D22 -> 1221855.7 | E24: =E11-E22 -> 1451632.7 | F24: =F11-F22 -> 1558003.3
A26: Interest: on Term Loan
A27: Interest: on CC
A28: D. Interest:
A30: E. Selling & Marketing Exp. | B30: 0 | C30: =B30+(B30*10%) -> 0 | D30: =C30+(C30*10%) -> 0 | E30: =D30+(D30*10%) -> 0 | F30: =E30+(E30*10%) -> 0
A32: F. Profit before Tax[ C - (D+E) ] | B32: =+B24-(B28+B30) -> 1049999.5 | C32: =+C24-(C28+C30) -> 1128854.6 | D32: =+D24-(D28+D30) -> 1221855.7 | E32: =+E24-(E28+E30) -> 1451632.7 | F32: =+F24-(F28+F30) -> 1558003.3
A34: G. Income Tax | B34: 0 | C34: 0 | D34: 0 | E34: 0 | F34: 0
A36: H. Profit after Tax ( F-G ) | B36: =B32-B34 -> 1049999.5 | C36: =C32-C34 -> 1128854.6 | D36: =D32-D34 -> 1221855.7 | E36: =E32-E34 -> 1451632.7 | F36: =F32-F34 -> 1558003.3
A38: I. Depreciation added back | B38: =B21 -> 1253917.5 | C38: =C21 -> 1065829.9 | D38: =D21 -> 905955.39 | E38: =E21 -> 770062.08 | F38: =F21 -> 654552.77
A40: J. Cash Accruals ( H + I ) | B40: =B36+B38 -> 2303917 | C40: =C36+C38 -> 2194684.5 | D40: =D36+D38 -> 2127811.1 | E40: =E36+E38 -> 2221694.8 | F40: =F36+F38 -> 2212556
A42: L. Repayment of Term Loan
A44: M. Net Cash A'ble (J - K)) | B44: =+B40-B42 -> 2303917 | C44: =+C40-C42 -> 2194684.5 | D44: =+D40-D42 -> 2127811.1 | E44: =+E40-E42 -> 2221694.8 | F44: =+F40-F42 -> 2212556

Sheet Cash
A1: =profit!A1 -> Ayan Sharma
A4: STATEMENT No.4
A6: CASH - FLOW STATEMENT :
A7: PARTICULARS | B7: Operating Years
B8: 2026 | C8: 2027 | D8: 2028 | E8: 2029 | F8: 2030
A9: A. Source of Funds :
A10: Profit after Tax | B10: =profit!B36 -> 1049999.5 | C10: =+profit!C36 -> 1128854.6 | D10: =+profit!D36 -> 1221855.7 | E10: =+profit!E36 -> 1451632.7 | F10: =+profit!F36 -> 1558003.3
A11: Depreciation | B11: =profit!B21 -> 1253917.5 | C11: =+profit!C21 -> 1065829.9 | D11: =+profit!D21 -> 905955.39 | E11: =+profit!E21 -> 770062.08 | F11: =+profit!F21 -> 654552.77
A12: Promoters Contribution | B12: =Cost!C34+Cost!C33 -> 7609070 | C12: 0 | D12: - | E12: - | F12: -
A13: Loan from Bank | B13: =Cost!C35+Cost!C36 -> 2300000 | C13: 0 | D13: - | E13: - | F13: -
A14: Subsidy from Government | B14: 0 | C14: 0 | D14: 0 | E14: 0 | F14: -
A16: TOTAL OF ' A ' | B16: =SUM(B10:B15) -> 12212987 | C16: =SUM(C10:C15) -> 2194684.5 | D16: =SUM(D10:D15) -> 2127811.1 | E16: =SUM(E10:E15) -> 2221694.8 | F16: =SUM(F10:F15) -> 2212556
A18: B. Application of Funds :
A19: Cost of the project | B19: =Cost!C29 -> 10209070 | C19: 0 | D19: - | E19: - | F19: -
A20: Repayment of loan | B20: =profit!B42 -> 0 | C20: =profit!C42 -> 0 | D20: =profit!D42 -> 0 | E20: =profit!E42 -> 0 | F20: =profit!F42 -> 0
A21: Interest: on Loan | B21: =profit!B28 -> 0 | C21: =profit!C28 -> 0 | D21: =profit!D28 -> 0 | E21: =profit!E28 -> 0 | F21: =profit!F28 -> 0
A23: TOTAL OF ' B ' | B23: =SUM(B19:B21) -> 10209070 | C23: =SUM(C19:C21) -> 0 | D23: =SUM(D19:D21) -> 0 | E23: =SUM(E19:E21) -> 0 | F23: =SUM(F19:F21) -> 0
A26: C. Opening Balance | B26: 125500 | C26: =B32 -> 1368307 | D26: =C32 -> 3516971.5 | E26: =D32 -> 5598732.7 | F26: =E32 -> 7745715.4
A28: D. Net surplus ( A - B ) | B28: =B16-B23 -> 2003917 | C28: =C16-C23 -> 2194684.5 | D28: =D16-D23 -> 2127811.1 | E28: =E16-E23 -> 2221694.8 | F28: =F16-F23 -> 2212556
A30: E. Drawings | B30: 761110 | C30: 46020 | D30: 46050 | E30: 74712 | F30: 46613
A32: F. Closing Balance | B32: =B26+B28-B30 -> 1368307 | C32: =C26+C28-C30 -> 3516971.5 | D32: =D26+D28-D30 -> 5598732.7 | E32: =E26+E28-E30 -> 7745715.4 | F32: =F26+F28-F30 -> 9911658.5

Sheet B.sheet
A1: =Cash!A1 -> Ayan Sharma
A4: STATEMENT No.5
A6: BALANCE SHEET
A8: PARTICULARS | B8: Operating Years
B9: 2026 | C9: 2027 | D9: 2028 | E9: 2029 | F9: 2030
A11: A. LIABILITIES :
A12: Capital Account | B12: =Cost!C34+Cost!C33 -> 7609070 | C12: =B12 -> 7609070 | D12: =+C12 -> 7609070 | E12: =+D12 -> 7609070 | F12: =+E12 -> 7609070
A13: Reserves & Surplus | B13: =profit!B36 -> 1049999.5 | C13: =B13+profit!C36 -> 2178854.1 | D13: =C13+profit!D36 -> 3400709.9 | E13: =D13+profit!E36 -> 4852342.6 | F13: =E13+profit!F36 -> 6410345.9
A14: Secured Loan- Term Loan
A15: Current Liabilities | B15: 165000 | C15: 225000 | D15: 265000 | E15: 300000 | F15: 350000
A16: Drawings
A18: TOTAL | B18: =SUM(B12:B17) -> 8824069.5 | C18: =SUM(C12:C17) -> 10012924 | D18: =SUM(D12:D17) -> 11274780 | E18: =SUM(E12:E17) -> 12761413 | F18: =SUM(F12:F17) -> 14369416
A21: B. ASSETS : | I21: =B26-B18 -> 0 | J21: 681630 | K21: 727680 | L21: 802392 | M21: 849005
A22: Fixed Assets | B22: =Depr.!B19 -> 7105532.5 | C22: =Depr.!C19 -> 6039702.6 | D22: =Depr.!D19 -> 5133747.2 | E22: =Depr.!E19 -> 4363685.1 | F22: =Depr.!F19 -> 3709132.4 | I22: =C26-C18 -> 0
A23: Current Assets | B23: 350230 | C23: 456250 | D23: 542300 | E23: 652012 | F23: 748625 | I23: =D26-D18 -> 0
A24: Cash & Bank | B24: =+Cash!B32 -> 1368307 | C24: =+Cash!C32 -> 3516971.5 | D24: =+Cash!D32 -> 5598732.7 | E24: =+Cash!E32 -> 7745715.4 | F24: =+Cash!F32 -> 9911658.5 | I24: =E26-E18 -> 0
I25: =F26-F18 -> 0
A26: TOTAL | B26: =SUM(B22:B25) -> 8824069.5 | C26: =SUM(C22:C25) -> 10012924 | D26: =SUM(D22:D25) -> 11274780 | E26: =SUM(E22:E25) -> 12761413 | F26: =SUM(F22:F25) -> 14369416
B29: =B18-B26 -> 0 | C29: =C18-C26 -> 0 | D29: =D18-D26 -> 0 | E29: =E18-E26 -> 0 | F29: =F18-F26 -> 0

Sheet Depr.
A1: =B.sheet!A1 -> Ayan Sharma
A4: ANNEXURE NO.1
A6: DEPRECIATION SCHEDULE:
A7: PARTICULARS | B7: WDV at the year end
B8: 2026 | C8: 2027 | D8: 2028 | E8: 2029 | F8: 2030
A10: Furniture & Fittings | B10: =Cost!B23 -> 0 | C10: =+B10-B11 -> 0 | D10: =+C10-C11 -> 0 | E10: =+D10-D11 -> 0 | F10: =+E10-E11 -> 0
A11: Depreciation @ 10% | B11: =+B10*10% -> 0 | C11: =+C10*10% -> 0 | D11: =+D10*10% -> 0 | E11: =+E10*10% -> 0 | F11: =+F10*10% -> 0
A12: WDV | B12: =B10-B11 -> 0 | C12: =C10-C11 -> 0 | D12: =D10-D11 -> 0 | E12: =E10-E11 -> 0 | F12: =F10-F11 -> 0
A14: =Cost!A18 -> Machinery & Equipments | B14: =3400000+4959450 -> 8359450 | C14: =+B14-B15 -> 7105532.5 | D14: =+C14-C15 -> 6039702.6 | E14: =+D14-D15 -> 5133747.2 | F14: =+E14-E15 -> 4363685.1
A15: Depreciation @ 15% | B15: =+B14*15% -> 1253917.5 | C15: =+C14*15% -> 1065829.9 | D15: =+D14*15% -> 905955.39 | E15: =+E14*15% -> 770062.08 | F15: =+F14*15% -> 654552.77
A16: WDV | B16: =B14-B15 -> 7105532.5 | C16: =C14-C15 -> 6039702.6 | D16: =D14-D15 -> 5133747.2 | E16: =E14-E15 -> 4363685.1 | F16: =F14-F15 -> 3709132.4
A19: Total Assets | B19: =B12+B16 -> 7105532.5 | C19: =C12+C16 -> 6039702.6 | D19: =D12+D16 -> 5133747.2 | E19: =E12+E16 -> 4363685.1 | F19: =F12+F16 -> 3709132.4
A22: Total Depreciation | B22: =B11+B15 -> 1253917.5 | C22: =C11+C15 -> 1065829.9 | D22: =D11+D15 -> 905955.39 | E22: =E11+E15 -> 770062.08 | F22: =F11+F15 -> 654552.77

Sheet BEP
A1: =Depr.!A1 -> Ayan Sharma
A4: ANNEXURE NO.2
A6: BREAK-EVEN ANALYSIS
B7: Years
B8: 2026 | C8: 2027 | D8: 2028 | E8: 2029 | F8: 2030
A9: A. Receipts | B9: =profit!B9 -> 15811417 | C9: =profit!C9 -> 16285760 | D9: =profit!D9 -> 16937190 | E9: =profit!E9 -> 17614677 | F9: =profit!F9 -> 18495411
A11: B. Variable cost: | B11: =profit!B22 -> 14761418 | C11: =profit!C22 -> 15156905 | D11: =profit!D22 -> 15715334 | E11: =profit!E22 -> 16163045 | F11: =profit!F22 -> 16937408
A14: D. Fixed costs:
A15: Depreciation | B15: =Depr.!B22 -> 1253917.5 | C15: =Depr.!C22 -> 1065829.9 | D15: =Depr.!D22 -> 905955.39 | E15: =Depr.!E22 -> 770062.08 | F15: =Depr.!F22 -> 654552.77
A16: Interest on Loan | B16: =profit!B28 -> 0 | C16: =profit!C28 -> 0 | D16: =profit!D28 -> 0 | E16: =profit!E28 -> 0 | F16: =profit!F28 -> 0
A17: Administration Expenses | B17: =profit!B30 -> 0 | C17: =profit!C30 -> 0 | D17: =profit!D30 -> 0 | E17: =profit!E30 -> 0 | F17: =profit!F30 -> 0
B18: =SUM(B15:B17) -> 1253917.5 | C18: =SUM(C15:C17) -> 1065829.9 | D18: =SUM(D15:D17) -> 905955.39 | E18: =SUM(E15:E17) -> 770062.08 | F18: =SUM(F15:F17) -> 654552.77
A20: E. Contribution [ B - C ] | B20: =B9 - B11 -> 1049999.5 | C20: =C9 - C11 -> 1128854.6 | D20: =D9 - D11 -> 1221855.7 | E20: =E9 - E11 -> 1451632.7 | F20: =F9 - F11 -> 1558003.3
A22: F. P.V.Ratio [ E/B x 100 ] | B22: =B20/B9*100 -> 6.6407679 | C22: =C20/C9*100 -> 6.9315443 | D22: =D20/D9*100 -> 7.2140405 | E22: =E20/E9*100 -> 8.2410405 | F22: =F20/F9*100 -> 8.4237287
A24: G. Break - even [ Value ]
A25: [ D / F x 100 ] | B25: =B18/B22*100 -> 18882116 | C25: =C18/C22*100 -> 15376514 | D25: =D18/D22*100 -> 12558224 | E25: =E18/E22*100 -> 9344233.7 | F25: =F18/F22*100 -> 7770344.9
A27: H. Cash Break Even | B27: =(B18-B15)/B22*100 -> 0 | C27: =(C18-C15)/C22*100 -> 0 | D27: =(D18-D15)/D22*100 -> 0 | E27: =(E18-E15)/E22*100 -> 0 | F27: =(F18-F15)/F22*100 -> 0
A28: [ Without Depreciation]

Sheet FI
A1: =Depr.!A1 -> Ayan Sharma
A4: ANNEXURE NO.3
A6: FINANCIAL INDICATERS
B7: Years
B8: 2026 | C8: 2027 | D8: 2028 | E8: 2029 | F8: 2030
A10: A. Shareholder Equity | B10: =B.sheet!B12+B.sheet!B13 -> 8659069.5 | C10: =B.sheet!C12+B.sheet!C13 -> 9787924.1 | D10: =B.sheet!D12+B.sheet!D13 -> 11009780 | E10: =B.sheet!E12+B.sheet!E13 -> 12461413 | F10: =B.sheet!F12+B.sheet!F13 -> 14019416
A12: B. Total Liabilities | B12: =B.sheet!B14+B.sheet!B15 -> 165000 | C12: =B.sheet!C14+B.sheet!C15 -> 225000 | D12: =B.sheet!D14+B.sheet!D15 -> 265000 | E12: =B.sheet!E14+B.sheet!E15 -> 300000 | F12: =B.sheet!F14+B.sheet!F15 -> 350000
A14: C. Debt Equity Ratio | B14: =B12/B10 -> 0.019055165 | C14: =C12/C10 -> 0.02298751 | D14: =D12/D10 -> 0.024069509 | E14: =E12/E10 -> 0.024074317 | F14: =F12/F10 -> 0.024965377
A16: D. Sales | B16: =profit!B9 -> 15811417 | C16: =profit!C9 -> 16285760 | D16: =profit!D9 -> 16937190 | E16: =profit!E9 -> 17614677 | F16: =profit!F9 -> 18495411
A18: E. Gross Profit | B18: =profit!B24 -> 1049999.5 | C18: =profit!C24 -> 1128854.6 | D18: =profit!D24 -> 1221855.7 | E18: =profit!E24 -> 1451632.7 | F18: =profit!F24 -> 1558003.3
A20: F. Net Profit | B20: =profit!B36 -> 1049999.5 | C20: =profit!C36 -> 1128854.6 | D20: =profit!D36 -> 1221855.7 | E20: =profit!E36 -> 1451632.7 | F20: =profit!F36 -> 1558003.3
A22: G. G.P.Ratio [ E/D x 100 ] | B22: =B18/B16*100 -> 6.6407679 | C22: =C18/C16*100 -> 6.9315443 | D22: =D18/D16*100 -> 7.2140405 | E22: =E18/E16*100 -> 8.2410405 | F22: =F18/F16*100 -> 8.4237287
A24: H. N.P.Ratio [ F/D x 100 ] | B24: =B20/B16*100 -> 6.6407679 | C24: =C20/C16*100 -> 6.9315443 | D24: =D20/D16*100 -> 7.2140405 | E24: =E20/E16*100 -> 8.2410405 | F24: =F20/F16*100 -> 8.4237287
A26: I. Total Current Assets | B26: =B.sheet!B23 -> 350230 | C26: =B.sheet!C23 -> 456250 | D26: =B.sheet!D23 -> 542300 | E26: =B.sheet!E23 -> 652012 | F26: =B.sheet!F23 -> 748625
A28: J. Total Current Liabilities | B28: =B.sheet!B15 -> 165000 | C28: =B.sheet!C15 -> 225000 | D28: =B.sheet!D15 -> 265000 | E28: =B.sheet!E15 -> 300000 | F28: =B.sheet!F15 -> 350000
A30: K.Current Ratio | B30: =B26/B28 -> 2.1226061 | C30: =C26/C28 -> 2.0277778 | D30: =D26/D28 -> 2.0464151 | E30: =E26/E28 -> 2.1733733 | F30: =F26/F28 -> 2.1389286

Sheet Interest
A1: =BEP!A1 -> Ayan Sharma
A3: ANNEXURE NO.4
A4: INTEREST SCHEDULE :
A5: NOTE : | B5: Interest on Term Loan is calculated at 11.00% per annum liquidated in 60 Months
A8: Sl. No | B8: BEGENING | C8: OPENING | D8: INSTALLMENT | E8: INTEREST | F8: PRINCIPAL | G8: CLOSING
B9: OF MONTH | C9: BALANCE | D9: REPAYMENT | E9: PER MONTH | F9: AMOUNT | G9: BALANCE
A11: 1 | B11: 1 | C11: =Cost!C35 -> 2300000 | D11: =-H11 -> 50007.573 | E11: =C11*11%*1/12 -> 21083.333 | F11: =D11-E11 -> 28924.24 | G11: =+C11-F11 -> 2271075.8 | H11: =PMT(11%/12,5*12,C11,0) -> -50007.573
A12: 2 | B12: 2 | C12: =G11 -> 2271075.8 | D12: =D11 -> 50007.573 | E12: =C12*11%*1/12 -> 20818.194 | F12: =D12-E12 -> 29189.379 | G12: =+C12-F12 -> 2241886.4
A13: 3 | B13: 3 | C13: =G12 -> 2241886.4 | D13: =D12 -> 50007.573 | E13: =C13*11%*1/12 -> 20550.625 | F13: =D13-E13 -> 29456.948 | G13: =+C13-F13 -> 2212429.4
A14: 4 | B14: 4 | C14: =+G13 -> 2212429.4 | D14: =D13 -> 50007.573 | E14: =C14*11%*1/12 -> 20280.603 | F14: =D14-E14 -> 29726.97 | G14: =+C14-F14 -> 2182702.5
A15: 5 | B15: 5 | C15: =+G14 -> 2182702.5 | D15: =D14 -> 50007.573 | E15: =C15*11%*1/12 -> 20008.106 | F15: =D15-E15 -> 29999.467 | G15: =+C15-F15 -> 2152703
A16: 6 | B16: 6 | C16: =+G15 -> 2152703 | D16: =D15 -> 50007.573 | E16: =C16*11%*1/12 -> 19733.111 | F16: =D16-E16 -> 30274.462 | G16: =+C16-F16 -> 2122428.5
A17: 7 | B17: 7 | C17: =+G16 -> 2122428.5 | D17: =D16 -> 50007.573 | E17: =C17*11%*1/12 -> 19455.595 | F17: =D17-E17 -> 30551.978 | G17: =+C17-F17 -> 2091876.6
A18: 8 | B18: 8 | C18: =+G17 -> 2091876.6 | D18: =D17 -> 50007.573 | E18: =C18*11%*1/12 -> 19175.535 | F18: =D18-E18 -> 30832.038 | G18: =+C18-F18 -> 2061044.5
A19: 9 | B19: 9 | C19: =+G18 -> 2061044.5 | D19: =D18 -> 50007.573 | E19: =C19*11%*1/12 -> 18892.908 | F19: =D19-E19 -> 31114.665 | G19: =+C19-F19 -> 2029929.9
A20: 10 | B20: 10 | C20: =+G19 -> 2029929.9 | D20: =D19 -> 50007.573 | E20: =C20*11%*1/12 -> 18607.69 | F20: =D20-E20 -> 31399.883 | G20: =+C20-F20 -> 1998530
A21: 11 | B21: 11 | C21: =+G20 -> 1998530 | D21: =D20 -> 50007.573 | E21: =C21*11%*1/12 -> 18319.858 | F21: =D21-E21 -> 31687.715 | G21: =+C21-F21 -> 1966842.3
A22: 12 | B22: 12 | C22: =+G21 -> 1966842.3 | D22: =D21 -> 50007.573 | E22: =C22*11%*1/12 -> 18029.387 | F22: =D22-E22 -> 31978.186 | G22: =+C22-F22 -> 1934864.1 | H22: =SUM(E11:E22) -> 234954.95 | I22: =SUM(F11:F22) -> 365135.93 | J22: =C22-I22 -> 1601706.3
A23: 13 | B23: 13 | C23: =+G22 -> 1934864.1 | D23: =D22 -> 50007.573 | E23: =C23*11%*1/12 -> 17736.254 | F23: =D23-E23 -> 32271.319 | G23: =+C23-F23 -> 1902592.8
A24: 14 | B24: 14 | C24: =+G23 -> 1902592.8 | D24: =D23 -> 50007.573 | E24: =C24*11%*1/12 -> 17440.434 | F24: =D24-E24 -> 32567.14 | G24: =+C24-F24 -> 1870025.6
A25: 15 | B25: 15 | C25: =+G24 -> 1870025.6 | D25: =D24 -> 50007.573 | E25: =C25*11%*1/12 -> 17141.901 | F25: =D25-E25 -> 32865.672 | G25: =+C25-F25 -> 1837159.9
A26: 16 | B26: 16 | C26: =+G25 -> 1837159.9 | D26: =D25 -> 50007.573 | E26: =C26*11%*1/12 -> 16840.633 | F26: =D26-E26 -> 33166.94 | G26: =+C26-F26 -> 1803993
A27: 17 | B27: 17 | C27: =+G26 -> 1803993 | D27: =D26 -> 50007.573 | E27: =C27*11%*1/12 -> 16536.602 | F27: =D27-E27 -> 33470.971 | G27: =+C27-F27 -> 1770522
A28: 18 | B28: 18 | C28: =+G27 -> 1770522 | D28: =D27 -> 50007.573 | E28: =C28*11%*1/12 -> 16229.785 | F28: =D28-E28 -> 33777.788 | G28: =+C28-F28 -> 1736744.2
A29: 19 | B29: 19 | C29: =+G28 -> 1736744.2 | D29: =D28 -> 50007.573 | E29: =C29*11%*1/12 -> 15920.156 | F29: =D29-E29 -> 34087.418 | G29: =+C29-F29 -> 1702656.8
A30: 20 | B30: 20 | C30: =+G29 -> 1702656.8 | D30: =D29 -> 50007.573 | E30: =C30*11%*1/12 -> 15607.688 | F30: =D30-E30 -> 34399.886 | G30: =+C30-F30 -> 1668256.9
A31: 21 | B31: 21 | C31: =+G30 -> 1668256.9 | D31: =D30 -> 50007.573 | E31: =C31*11%*1/12 -> 15292.355 | F31: =D31-E31 -> 34715.218 | G31: =+C31-F31 -> 1633541.7
A32: 22 | B32: 22 | C32: =+G31 -> 1633541.7 | D32: =D31 -> 50007.573 | E32: =C32*11%*1/12 -> 14974.132 | F32: =D32-E32 -> 35033.441 | G32: =+C32-F32 -> 1598508.3
A33: 23 | B33: 23 | C33: =+G32 -> 1598508.3 | D33: =D32 -> 50007.573 | E33: =C33*11%*1/12 -> 14652.993 | F33: =D33-E33 -> 35354.581 | G33: =+C33-F33 -> 1563153.7
A34: 24 | B34: 24 | C34: =+G33 -> 1563153.7 | D34: =D33 -> 50007.573 | E34: =C34*11%*1/12 -> 14328.909 | F34: =D34-E34 -> 35678.664 | G34: =+C34-F34 -> 1527475 | H34: =SUM(E23:E34) -> 192701.84 | I34: =SUM(F23:F34) -> 407389.04 | J34: =C34-I34 -> 1155764.7
A35: 25 | B35: 25 | C35: =+G34 -> 1527475 | D35: =D34 -> 50007.573 | E35: =C35*11%*1/12 -> 14001.854 | F35: =D35-E35 -> 36005.719 | G35: =+C35-F35 -> 1491469.3
A36: 26 | B36: 26 | C36: =+G35 -> 1491469.3 | D36: =D35 -> 50007.573 | E36: =C36*11%*1/12 -> 13671.802 | F36: =D36-E36 -> 36335.771 | G36: =+C36-F36 -> 1455133.5
A37: 27 | B37: 27 | C37: =+G36 -> 1455133.5 | D37: =D36 -> 50007.573 | E37: =C37*11%*1/12 -> 13338.724 | F37: =D37-E37 -> 36668.849 | G37: =+C37-F37 -> 1418464.7
A38: 28 | B38: 28 | C38: =+G37 -> 1418464.7 | D38: =D37 -> 50007.573 | E38: =C38*11%*1/12 -> 13002.593 | F38: =D38-E38 -> 37004.98 | G38: =+C38-F38 -> 1381459.7
A39: 29 | B39: 29 | C39: =+G38 -> 1381459.7 | D39: =D38 -> 50007.573 | E39: =C39*11%*1/12 -> 12663.381 | F39: =D39-E39 -> 37344.192 | G39: =+C39-F39 -> 1344115.5
A40: 30 | B40: 30 | C40: =+G39 -> 1344115.5 | D40: =D39 -> 50007.573 | E40: =C40*11%*1/12 -> 12321.059 | F40: =D40-E40 -> 37686.514 | G40: =+C40-F40 -> 1306429
A41: 31 | B41: 31 | C41: =+G40 -> 1306429 | D41: =D40 -> 50007.573 | E41: =C41*11%*1/12 -> 11975.599 | F41: =D41-E41 -> 38031.974 | G41: =+C41-F41 -> 1268397
A42: 32 | B42: 32 | C42: =+G41 -> 1268397 | D42: =D41 -> 50007.573 | E42: =C42*11%*1/12 -> 11626.973 | F42: =D42-E42 -> 38380.6 | G42: =+C42-F42 -> 1230016.4
A43: 33 | B43: 33 | C43: =+G42 -> 1230016.4 | D43: =D42 -> 50007.573 | E43: =C43*11%*1/12 -> 11275.151 | F43: =D43-E43 -> 38732.422 | G43: =+C43-F43 -> 1191284
A44: 34 | B44: 34 | C44: =+G43 -> 1191284 | D44: =D43 -> 50007.573 | E44: =C44*11%*1/12 -> 10920.103 | F44: =D44-E44 -> 39087.47 | G44: =+C44-F44 -> 1152196.5
...

Sheet Annex 5 DSCR
A1: =Interest!A1 -> Ayan Sharma
A4: ANNEXURE NO.5
A6: DEBT SERVICE COVERAGE RATIO :
B7: Operating Years
B8: 2026 | C8: 2027 | D8: 2028 | E8: 2029 | F8: 2030
A9: A. SOURCES :
A10: Profit after tax | B10: =+profit!B36 -> 1049999.5 | C10: =+profit!C36 -> 1128854.6 | D10: =+profit!D36 -> 1221855.7 | E10: =+profit!E36 -> 1451632.7 | F10: =+profit!F36 -> 1558003.3
A11: Depreciation | B11: =+profit!B38 -> 1253917.5 | C11: =+profit!C38 -> 1065829.9 | D11: =+profit!D38 -> 905955.39 | E11: =+profit!E38 -> 770062.08 | F11: =+profit!F38 -> 654552.77
A12: Interest on Loan | B12: =profit!B28 -> 0 | C12: =profit!C28 -> 0 | D12: =profit!D28 -> 0 | E12: =profit!E28 -> 0 | F12: =profit!F28 -> 0
A13: TOTAL OF ' A ' | B13: =SUM(B10:B12) -> 2303917 | C13: =SUM(C10:C12) -> 2194684.5 | D13: =SUM(D10:D12) -> 2127811.1 | E13: =SUM(E10:E12) -> 2221694.8 | F13: =SUM(F10:F12) -> 2212556
A15: B DEBT :
A16: Term loan installment | B16: =+Cash!B20 -> 0 | C16: =+Cash!C20 -> 0 | D16: =+Cash!D20 -> 0 | E16: =+Cash!E20 -> 0 | F16: =+Cash!F20 -> 0
A17: Interest on Loan | B17: =profit!B28 -> 0 | C17: =profit!C28 -> 0 | D17: =profit!D28 -> 0 | E17: =profit!E28 -> 0 | F17: =profit!F28 -> 0
A19: TOTAL OF ' B ' | B19: =SUM(B16:B18) -> 0 | C19: =SUM(C16:C18) -> 0 | D19: =SUM(D16:D18) -> 0 | E19: =SUM(E16:E18) -> 0 | F19: =SUM(F16:F18) -> 0
A21: C Debt Service Coverage Ratio
A22: DSCR [ A / B ] | B22: =B13/B19 -> #DIV/0! | C22: =C13/C19 -> #DIV/0! | D22: =D13/D19 -> #DIV/0! | E22: =E13/E19 -> #DIV/0! | F22: =F13/F19 -> #DIV/0!
A24: D Average DSCR | B24: =AVERAGE(B22:F22) -> #DIV/0!

Sheet Annex 6 ROI
A1: ='Annex 5 DSCR'!A1 -> Ayan Sharma
A4: ANNEXURE NO.6
A6: ANALYSIS OF RETURN ON INVESTMENT :
A8: 1. Return on Investment = | B8: Average Return x 100
B9: Capital Employed
A11: 2. Return = | B11: Profit before tax + Depreciation + Interest on term loan
A13: 3. Capital Employed = | B13: Cost of the Project
A15: RETURN ON INVESTMENT :
A17: PARTICULARS | B17: O P E R T I N G Y E A R S
B18: 2026 | C18: 2027 | D18: 2028 | E18: 2029 | F18: 2030
A19: Profit before tax | B19: =+profit!B32 -> 1049999.5 | C19: =+profit!C32 -> 1128854.6 | D19: =+profit!D32 -> 1221855.7 | E19: =+profit!E32 -> 1451632.7 | F19: =+profit!F32 -> 1558003.3
A21: Depreciation | B21: =+profit!B38 -> 1253917.5 | C21: =+profit!C38 -> 1065829.9 | D21: =+profit!D38 -> 905955.39 | E21: =+profit!E38 -> 770062.08 | F21: =+profit!F38 -> 654552.77
A23: Interest on Loan | B23: =+profit!B28 -> 0 | C23: =+profit!C28 -> 0 | D23: =+profit!D28 -> 0 | E23: =+profit!E28 -> 0 | F23: =+profit!F28 -> 0
B26: =SUM(B19:B24) -> 2303917 | C26: =SUM(C19:C24) -> 2194684.5 | D26: =SUM(D19:D24) -> 2127811.1 | E26: =SUM(E19:E24) -> 2221694.8 | F26: =SUM(F19:F24) -> 2212556
A30: # Average Return | B30: =SUM(B26:F27)/5 -> 2212132.7
A32: # Capital Employed | B32: =Cost!C38 -> 9909070
A34: # Return on Investment | B34: =+B30/B32% -> 22.324322 | C34: %

Sheet Assumptions
A1: ='Annex 6 ROI'!A1 -> Ayan Sharma
A4: ANNEXURE NO.7
A5: Assumption and workings notes to the Financial Statements of the Project Report:
A8: 3 | B8: Salary
B9: S.No. | C9: Category of Employee | E9: No.of | F9: Salary per | G9: Salary per
E10: Employees | F10: Month | G10: Annuam
B11: 1 | C11: SKILLED | E11: 6 | F11: 30000 | G11: =F11*E11*12 -> 2160000
B13: 2 | C13: UNSKILLED | E13: 2 | F13: 15000 | G13: =F13*E13*12 -> 360000
C15: Total | E15: =SUM(E11:E14) -> 8 | G15: =SUM(G11:G14) -> 2520000
B16: Note: Increament in salary is taken at 10% per annum
A18: 4 | B18: Power
B19: Fuel & Power Charges is estimated at Rs.5000/- per month and provision made for increase
B20: in rates @ 5% per annuam
A22: 5 | B22: Depreciation:
B23: Depreciation is calculated at the rates prescribed under
B24: the Income Tax Act. Separate Annexure made
A26: 6 | B26: Interest:
B27: Interest on term loan is calculated at 11.00% per annum
B28: Term loan will be repaid in 5 year
A31: 7 | B31: Selling and Administration Expenses:
B32: Selling expenses includes sales commission, Post & Telephone expenses and other
B33: Office maintenance expenses.
B34: It is estimated at Rs. 50,000/- per year and provision made for increase in cost
B35: at 10% per annuam
